2025-09-11 16:51:56,340 INFO:Auto-tuning with 0.9 CPU utilizations, 8 CPUs available, 7 CPUs will be used
2025-09-11 16:52:05,965 INFO:An error occurred while testing config {'BLOCK_N': 128, 'reduce_threads': 32}, checkout autotuner.log for more details
2025-09-11 16:52:05,968 DEBUG:Error: Traceback (most recent call last):
  File "/storage/coda1/p-tkrishna3/0/hkang342/h100/lib/python3.12/site-packages/tilelang/autotuner/tuner.py", line 499, in run
    latency, ref_latency = run_with_timeout(target_fn, timeout, jit_kernel)
                           ^^^^^^^^^^^^^^^^^^^^^^^^^^^^^^^^^^^^^^^^^^^^^^^^
  File "/storage/coda1/p-tkrishna3/0/hkang342/h100/lib/python3.12/site-packages/tilelang/autotuner/tuner.py", line 55, in run_with_timeout
    raise e
  File "/storage/coda1/p-tkrishna3/0/hkang342/h100/lib/python3.12/site-packages/tilelang/autotuner/tuner.py", line 53, in run_with_timeout
    result = func(*args, **kwargs)
             ^^^^^^^^^^^^^^^^^^^^^
  File "/storage/coda1/p-tkrishna3/0/hkang342/h100/lib/python3.12/site-packages/tilelang/autotuner/tuner.py", line 392, in target_fn
    latency = profiler.do_bench(
              ^^^^^^^^^^^^^^^^^^
  File "/storage/coda1/p-tkrishna3/0/hkang342/h100/lib/python3.12/site-packages/tilelang/profiler/__init__.py", line 240, in do_bench
    return do_bench(
           ^^^^^^^^^
  File "/storage/coda1/p-tkrishna3/0/hkang342/h100/lib/python3.12/site-packages/tilelang/profiler/bench.py", line 41, in do_bench
    fn()
  File "/storage/coda1/p-tkrishna3/0/hkang342/h100/lib/python3.12/site-packages/tilelang/jit/adapter/base.py", line 49, in __call__
    return self.func(*args, **kwds)
           ^^^^^^^^^^^^^^^^^^^^^^^^
  File "/storage/coda1/p-tkrishna3/0/hkang342/h100/lib/python3.12/site-packages/tilelang/jit/adapter/cython/adapter.py", line 447, in lambda_forward
    return self.cython_wrapper.forward([*args],
           ^^^^^^^^^^^^^^^^^^^^^^^^^^^^^^^^^^^^
  File "tilelang/jit/adapter/cython/cython_wrapper.pyx", line 107, in tilelang.jit.adapter.cython.cython_wrapper.CythonKernelWrapper.forward
  File "tilelang/jit/adapter/cython/cython_wrapper.pyx", line 206, in tilelang.jit.adapter.cython.cython_wrapper.CythonKernelWrapper.forward
RuntimeError: Kernel call failed: kernel_name: cudaErrorInvalidConfiguration - invalid configuration argument

